Workbook

Sheet Raw_Data
A1: student_id | B1: age | C1: gender | D1: year_of_study | E1: major_category | F1: daily_sleep_hours | G1: daily_screen_time_hours | H1: physical_activity_days_per_week | I1: phq9_score | J1: gad7_score | K1: perceived_stress_scale | L1: weekly_study_hours | M1: class_attendance_percent | N1: online_learning_satisfaction | O1: has_part_time_job | P1: financial_stress | Q1: semester_type | R1: cgpa | S1: gender_cleaned
A2: STU1001 | B2: 22 | C2: Female | D2: 3 | E2: Business | F2: 6.1 | G2: 4.1 | H2: 1 | I2: 17 | J2: 16 | K2: 26 | L2: 6.3 | M2: 63.9 | N2: 5 | O2: No | P2: 1 | Q2: Spring | R2: 2.46 | S2: Female
A3: STU1002 | B3: 19 | C3: M | D3: 2 | E3: Business | F3: 7 | G3: 2.3 | H3: 3 | I3: 9 | J3: 7 | K3: 19 | L3: 20.7 | M3: 78.5 | N3: 3 | O3: No | P3: 4 | Q3: Fall | R3: 2.98 | S3: Male
A4: STU1003 | B4: 23 | C4: Prefer not to say | D4: 3 | E4: STEM | F4: 5 | G4: 9.2 | H4: 1 | I4: 1 | J4: 2 | K4: 10 | L4: 17.1 | M4: 92.5 | N4: 5 | O4: No | P4: 3 | Q4: Spring | R4: 3.27 | S4: Prefer not to say
A5: STU1004 | B5: 23 | C5: Male | D5: 2 | E5: Humanities | F5: 3.8 | G5: 2 | H5: 6 | I5: 4 | J5: 6 | K5: 9 | L5: 25.2 | M5: 86.5 | N5: 3 | O5: Yes | P5: 2 | Q5: Spring | R5: 3.09 | S5: Male
A6: STU1005 | B6: 17 | C6: Female | D6: 5 | E6: Arts | F6: 5.8 | G6: 4.1 | H6: 0 | I6: 10 | J6: 6 | K6: 15 | L6: 4.6 | M6: 83.9 | N6: 5 | O6: Yes | P6: 3 | Q6: Spring | R6: 2.28 | S6: Female
A7: STU1006 | B7: 19 | C7: Female | D7: 2 | E7: Business | F7: 5.2 | G7: 5.8 | H7: 4 | I7: 5 | J7: 5 | K7: 8 | L7: 12.5 | M7: 78.4 | N7: 2 | O7: No | P7: 3 | Q7: Spring | R7: 2.69 | S7: Female
A8: STU1007 | B8: 22 | C8: Male | D8: 3 | E8: Humanities | F8: 4.3 | G8: 4.6 | H8: 4 | I8: 3 | J8: 3 | K8: 5 | L8: 20.8 | M8: 75.5 | N8: 4 | O8: No | P8: 3 | Q8: Fall | R8: 2.9 | S8: Male
A9: STU1008 | B9: 21 | C9: male | D9: 1 | E9: STEM | F9: 8.3 | G9: 5.3 | H9: 0 | I9: 27 | J9: 19 | K9: 28 | L9: 24.6 | M9: 71.2 | N9: 2 | O9: No | P9: 5 | Q9: Fall | S9: Male
A10: STU1009 | B10: 21 | C10: Female | D10: 2 | E10: STEM | F10: 6.8 | G10: 2.3 | H10: 1 | I10: 7 | J10: 8 | K10: 12 | L10: 32.7 | M10: 96 | N10: 5 | O10: No | P10: 4 | Q10: Spring | R10: 3.18 | S10: Female
A11: STU1010 | B11: 20 | C11: Female | D11: 4 | E11: STEM | F11: 6.6 | G11: 5.9 | H11: 2 | I11: 6 | J11: 7 | K11: 13 | L11: 20.8 | M11: 97.1 | N11: 5 | O11: No | P11: 4 | Q11: Fall | R11: 3.11 | S11: Female
A12: STU1011 | B12: 23 | C12: Male | D12: 3 | E12: STEM | F12: 6.1 | G12: 1.1 | H12: 5 | I12: 8 | J12: 6 | K12: 7 | L12: 31.6 | M12: 65.6 | N12: 3 | O12: No | P12: 3 | Q12: Spring | R12: 2.85 | S12: Male
A13: STU1012 | B13: 23 | C13: Male | D13: 2 | E13: Arts | F13: 5.2 | G13: 9.1 | H13: 3 | I13: 4 | J13: 5 | K13: 10 | L13: 11.5 | M13: 89 | N13: 3 | O13: Yes | P13: 5 | Q13: Spring | R13: 2.43 | S13: Male
A14: STU1013 | B14: 22 | C14: female | D14: 5 | E14: Business | F14: 8.2 | G14: 1 | H14: 3 | K14: 21 | L14: 24.5 | M14: 71.8 | N14: 4 | O14: No | P14: 2 | Q14: Spring | R14: 3.13 | S14: Female
A15: STU1014 | B15: 24 | C15: Male | D15: 4 | E15: Health Sciences | F15: 6.4 | G15: 2.9 | H15: 4 | I15: 7 | J15: 5 | K15: 15 | L15: 11.4 | M15: 86.2 | N15: 3 | O15: No | P15: 2 | Q15: Spring | R15: 3.1 | S15: Male
A16: STU1015 | B16: 22 | C16: Male | D16: 2 | E16: Social Sciences | F16: 7.6 | G16: 4.1 | H16: 4 | I16: 6 | J16: 6 | K16: 10 | L16: 18.9 | M16: 75.7 | N16: 4 | O16: No | P16: 1 | Q16: Spring | R16: 4.1 | S16: Male
A17: STU1016 | B17: 20 | C17: Male | D17: 3 | E17: STEM | F17: 5.5 | G17: 8.8 | H17: 3 | I17: 27 | J17: 19 | K17: 27 | L17: 1.5 | M17: 97.8 | O17: No | P17: 3 | Q17: Summer | R17: 2.37 | S17: Male
A18: STU1017 | B18: 22 | C18: Female | D18: 3 | E18: STEM | F18: 5.9 | G18: 2 | H18: 3 | I18: 4 | J18: 4 | K18: 11 | L18: 15.4 | M18: 75.3 | N18: 3 | O18: Yes | P18: 3 | Q18: Fall | R18: 3.37 | S18: Female
A19: STU1018 | B19: 19 | C19: Female | D19: 3 | E19: Health Sciences | F19: 4.6 | G19: 7.3 | H19: 4 | I19: 3 | J19: 1 | K19: 1 | L19: 23.7 | M19: 85.9 | N19: 2 | O19: Yes | P19: 4 | Q19: Spring | R19: 2.99 | S19: Female
A20: STU1019 | B20: 23 | C20: Female | D20: 2 | E20: STEM | F20: 4.5 | G20: 1 | H20: 2 | I20: 7 | J20: 9 | K20: 17 | L20: 11.9 | M20: 92 | N20: 5 | O20: No | P20: 3 | Q20: Fall | R20: 2.78 | S20: Female
A21: STU1020 | B21: 21 | C21: Male | D21: 2 | E21: Arts | F21: 6.4 | G21: 2.8 | H21: 5 | I21: 4 | J21: 3 | K21: 8 | L21: 17.5 | M21: 66.7 | N21: 2 | O21: No | P21: 1 | Q21: Spring | R21: 2.73 | S21: Male
A22: STU1021 | B22: 21 | C22: Male | D22: 4 | E22: STEM | F22: 7.1 | G22: 1 | H22: 0 | I22: 7 | J22: 9 | K22: 19 | L22: 26.8 | M22: 80 | N22: 4 | O22: Yes | P22: 4 | Q22: Spring | R22: 3.29 | S22: Male
A23: STU1022 | B23: 20 | C23: M | D23: 4 | E23: Social Sciences | F23: 4.5 | G23: 4.3 | H23: 1 | I23: 2 | J23: 2 | K23: 2 | L23: 14.1 | M23: 72.7 | N23: 2 | O23: No | P23: 5 | Q23: Spring | R23: 2.88 | S23: Male
A24: STU1023 | B24: 24 | C24: Female | D24: 4 | E24: Health Sciences | F24: 6.4 | G24: 2.4 | H24: 4 | I24: 13 | J24: 9 | K24: 20 | L24: 14.7 | M24: 69.3 | N24: 2 | O24: Yes | P24: 2 | Q24: Spring | R24: 2.96 | S24: Female
A25: STU1024 | B25: 21 | C25: Female | D25: 5 | E25: STEM | F25: 6.5 | G25: 2.6 | H25: 2 | I25: 25 | J25: 21 | K25: 31 | L25: 12.8 | M25: 62.4 | N25: 1 | O25: No | P25: 2 | Q25: Spring | R25: 2.26 | S25: Female
A26: STU1025 | B26: 21 | C26: Non-binary | D26: 4 | E26: STEM | F26: 3 | G26: 10.6 | H26: 1 | I26: 4 | J26: 7 | K26: 10 | L26: 13.2 | M26: 97.3 | N26: 3 | O26: No | P26: 2 | Q26: Fall | R26: 3.06 | S26: Non-binary
A27: STU1026 | B27: 21 | C27: male | D27: 4 | E27: Law | F27: 5.3 | G27: 2.9 | H27: 1 | I27: 3 | J27: 4 | K27: 5 | L27: 19 | M27: 73.8 | N27: 4 | O27: Yes | P27: 3 | Q27: Spring | R27: 2.88 | S27: Male
A28: STU1027 | B28: 23 | C28: Male | D28: 4 | E28: STEM | F28: 6.5 | G28: 9.7 | H28: 3 | K28: 11 | L28: 21.1 | M28: 88.4 | N28: 3 | O28: No | P28: 2 | Q28: Fall | R28: 3.31 | S28: Male
A29: STU1028 | B29: 22 | C29: Female | D29: 3 | E29: Business | F29: 7.1 | G29: 2.3 | H29: 4 | I29: 3 | J29: 3 | K29: 10 | L29: 13.2 | M29: 83.8 | N29: 4 | O29: No | P29: 3 | Q29: Summer | R29: 2.96 | S29: Female
A30: STU1029 | B30: 22 | C30: Female | D30: 2 | E30: Business | F30: 4.5 | G30: 4.6 | H30: 0 | I30: 3 | J30: 4 | K30: 14 | L30: 34.4 | M30: 66.7 | N30: 4 | O30: No | P30: 4 | Q30: Spring | R30: 3.31 | S30: Female
A31: STU1030 | B31: 22 | C31: Female | D31: 2 | E31: STEM | F31: 6 | G31: 4.2 | H31: 0 | I31: 14 | J31: 10 | K31: 22 | L31: 11.7 | M31: 80 | N31: 2 | O31: Yes | P31: 3 | Q31: Spring | R31: 3.32 | S31: Female
A32: STU1031 | B32: 26 | C32: M | D32: 3 | E32: Social Sciences | F32: 7.5 | G32: 8.6 | H32: 3 | I32: 3 | J32: 6 | K32: 8 | L32: 27.2 | M32: 63.4 | N32: 1 | O32: Yes | P32: 3 | Q32: Summer | R32: 2.78 | S32: Male
A33: STU1032 | B33: 21 | C33: Female | D33: 2 | E33: Social Sciences | F33: 6.9 | G33: 6.7 | H33: 6 | I33: 2 | J33: 2 | K33: 4 | L33: 11.1 | M33: 90.5 | N33: 4 | O33: No | P33: 1 | Q33: Spring | R33: 3.34 | S33: Female
A34: STU1033 | B34: 20 | C34: male | D34: 2 | E34: Business | F34: 6.1 | G34: 3.4 | H34: 2 | I34: 6 | J34: 9 | K34: 9 | L34: 18.1 | M34: 67.4 | N34: 4 | O34: No | P34: 5 | Q34: Spring | R34: 2.28 | S34: Male
A35: STU1034 | B35: 20 | C35: M | D35: 3 | E35: Health Sciences | F35: 5.4 | G35: 6.6 | H35: 6 | I35: 4 | J35: 4 | K35: 14 | L35: 28.3 | M35: 84.6 | N35: 3 | O35: No | P35: 3 | Q35: Fall | R35: 3.26 | S35: Male
A36: STU1035 | B36: 23 | C36: Female | D36: 2 | E36: STEM | F36: 4.8 | G36: 6.3 | H36: 5 | I36: 12 | J36: 10 | K36: 15 | L36: 26.7 | M36: 56.6 | N36: 2 | O36: No | P36: 3 | Q36: Fall | R36: 2.24 | S36: Female
A37: STU1036 | B37: 24 | C37: female | D37: 1 | E37: STEM | F37: 7.5 | G37: 2.1 | H37: 2 | I37: 6 | J37: 7 | K37: 16 | L37: 16.7 | M37: 80.9 | N37: 4 | O37: No | P37: 1 | Q37: Summer | R37: 2.97 | S37: Female
A38: STU1037 | B38: 21 | C38: Female | D38: 4 | E38: Humanities | F38: 5.7 | G38: 10.1 | H38: 4 | I38: 6 | J38: 6 | K38: 13 | L38: 18.8 | M38: 89.4 | N38: 1 | O38: Yes | P38: 4 | Q38: Summer | R38: 2.57 | S38: Female
A39: STU1038 | B39: 20 | C39: M | D39: 4 | E39: Law | F39: 6.6 | G39: 11.2 | H39: 4 | I39: 6 | J39: 5 | K39: 12 | L39: 24.3 | M39: 74.1 | N39: 4 | O39: No | P39: 5 | Q39: Spring | R39: 3.11 | S39: Male
A40: STU1039 | B40: 20 | C40: Female | D40: 1 | E40: STEM | F40: 6.3 | G40: 5.2 | H40: 3 | I40: 8 | J40: 7 | K40: 12 | L40: 15.6 | M40: 66.7 | N40: 2 | O40: No | P40: 1 | Q40: Fall | R40: 3.16 | S40: Female
...

Sheet Clean_Data
A1: Student Mental Health - Hybrid Learning
A3: 1 | B3: 2 | C3: 3 | D3: 4 | E3: 5 | F3: 6 | G3: 7 | H3: 8 | I3: 9 | J3: 10 | K3: 11 | L3: 12 | M3: 13 | N3: 14 | O3: 15 | P3: 16 | Q3: 17 | R3: 18 | S3: 19 | T3: 20 | U3: 21 | V3: 22 | W3: 23 | X3: 24 | Y3: 25
A4: student_id | B4: age | C4: gender | D4: year_of_study | E4: major_category | F4: daily_sleep_hours | G4: daily_screen_time_hours | H4: physical_activity_days_per_week | I4: phq9_score | J4: gad7_score | K4: phq9_score_category | L4: perceived_stress_scale | M4: gad7_score_interpretation | N4: weekly_study_hours | O4: pss_category | P4: class_attendance_percent | Q4: online_learning_satisfaction | R4: attendance_band | S4: has_part_time_job | T4: financial_stress | U4: semester_type | V4: cgpa | W4: screen_time_band | X4: sleep_hour_band | Y4: gender_cleaned
A5: STU1001 | B5: 22 | C5: Female | D5: 3 | E5: Business | F5: 6.1 | G5: 4.1 | H5: 1 | I5: 17 | J5: 16 | K5: {=_xlfn.IFS(stdsurvey[[#This Row],[phq9_score]]="","Answer Not Provided",stdsurvey[[#This Row],[phq9_score]]<=4,"Minimal",stdsurvey[[#This Row],[phq9_score]]<=9,"Mild",stdsurvey[[#This Row],[phq9_score]]<=14,"Moderate",stdsurvey[[#This Row],[phq9_score]]<=19,"Moderately Severe",stdsurvey[[#This Row],[phq9_score]]<=27,"Severe")} -> Moderately Severe | L5: 26 | M5: {=_xlfn.IFS(stdsurvey[[#This Row],[gad7_score]]="","Answer Not Provided",stdsurvey[[#This Row],[gad7_score]]<=4,"Minimal",stdsurvey[[#This Row],[gad7_score]]<=9,"Mild",stdsurvey[[#This Row],[gad7_score]]<=14,"Moderate",stdsurvey[[#This Row],[gad7_score]]<=21,"Severe")} -> Severe | N5: 6.3 | O5: {=_xlfn.IFS(stdsurvey[[#This Row],[perceived_stress_scale]]="","Answer Not Provided",stdsurvey[[#This Row],[perceived_stress_scale]]<=13,"Low Stress",stdsurvey[[#This Row],[perceived_stress_scale]]<=26,"Moderate Stress",stdsurvey[[#This Row],[perceived_stress_scale]]<=40,"High Stress")} -> Moderate Stress | P5: 63.9 | Q5: 5 | R5: {=_xlfn.IFS(stdsurvey[[#This Row],[class_attendance_percent]]<60,"Less than 0%",stdsurvey[[#This Row],[class_attendance_percent]]<70,"60-70 %",stdsurvey[[#This Row],[class_attendance_percent]]<80, "70-80%",stdsurvey[[#This Row],[class_attendance_percent]]<90,"80-90%",TRUE,"More than 90%")} -> 60-70 % | S5: No | T5: 1 | U5: Spring | V5: 2.46 | W5: {=_xlfn.IFS( stdsurvey[[#This Row],[daily_screen_time_hours]]<1,"<1 hr", stdsurvey[[#This Row],[daily_screen_time_hours]]<4,"1-4 hrs", stdsurvey[[#This Row],[daily_screen_time_hours]]<8,"4-8 hrs", stdsurvey[[#This Row],[daily_screen_time_hours]]<12,"8-12 hrs", stdsurvey[[#This Row],[daily_screen_time_hours]]<=16,"12-16 hrs", TRUE,">16 hrs" )} -> 4-8 hrs | X5: {=_xlfn.IFS(stdsurvey[[#This Row],[daily_sleep_hours]]<4,"< 4 hrs",stdsurvey[[#This Row],[daily_sleep_hours]]<=6,"4-6 hrs",stdsurvey[[#This Row],[daily_sleep_hours]]<=8,"6-8 hrs",TRUE,"> 8 hrs")} -> 6-8 hrs | Y5: Female
A6: STU1002 | B6: 19 | C6: M | D6: 2 | E6: Business | F6: 7 | G6: 2.3 | H6: 3 | I6: 9 | J6: 7 | K6: {=_xlfn.IFS(stdsurvey[[#This Row],[phq9_score]]="","Answer Not Provided",stdsurvey[[#This Row],[phq9_score]]<=4,"Minimal",stdsurvey[[#This Row],[phq9_score]]<=9,"Mild",stdsurvey[[#This Row],[phq9_score]]<=14,"Moderate",stdsurvey[[#This Row],[phq9_score]]<=19,"Moderately Severe",stdsurvey[[#This Row],[phq9_score]]<=27,"Severe")} -> Mild | L6: 19 | M6: {=_xlfn.IFS(stdsurvey[[#This Row],[gad7_score]]="","Answer Not Provided",stdsurvey[[#This Row],[gad7_score]]<=4,"Minimal",stdsurvey[[#This Row],[gad7_score]]<=9,"Mild",stdsurvey[[#This Row],[gad7_score]]<=14,"Moderate",stdsurvey[[#This Row],[gad7_score]]<=21,"Severe")} -> Mild | N6: 20.7 | O6: {=_xlfn.IFS(stdsurvey[[#This Row],[perceived_stress_scale]]="","Answer Not Provided",stdsurvey[[#This Row],[perceived_stress_scale]]<=13,"Low Stress",stdsurvey[[#This Row],[perceived_stress_scale]]<=26,"Moderate Stress",stdsurvey[[#This Row],[perceived_stress_scale]]<=40,"High Stress")} -> Moderate Stress | P6: 78.5 | Q6: 3 | R6: {=_xlfn.IFS(stdsurvey[[#This Row],[class_attendance_percent]]<60,"Less than 0%",stdsurvey[[#This Row],[class_attendance_percent]]<70,"60-70 %",stdsurvey[[#This Row],[class_attendance_percent]]<80, "70-80%",stdsurvey[[#This Row],[class_attendance_percent]]<90,"80-90%",TRUE,"More than 90%")} -> 70-80% | S6: No | T6: 4 | U6: Fall | V6: 2.98 | W6: {=_xlfn.IFS( stdsurvey[[#This Row],[daily_screen_time_hours]]<1,"<1 hr", stdsurvey[[#This Row],[daily_screen_time_hours]]<4,"1-4 hrs", stdsurvey[[#This Row],[daily_screen_time_hours]]<8,"4-8 hrs", stdsurvey[[#This Row],[daily_screen_time_hours]]<12,"8-12 hrs", stdsurvey[[#This Row],[daily_screen_time_hours]]<=16,"12-16 hrs", TRUE,">16 hrs" )} -> 1-4 hrs | X6: {=_xlfn.IFS(stdsurvey[[#This Row],[daily_sleep_hours]]<4,"< 4 hrs",stdsurvey[[#This Row],[daily_sleep_hours]]<=6,"4-6 hrs",stdsurvey[[#This Row],[daily_sleep_hours]]<=8,"6-8 hrs",TRUE,"> 8 hrs")} -> 6-8 hrs | Y6: Male
A7: STU1003 | B7: 23 | C7: Prefer not to say | D7: 3 | E7: STEM | F7: 5 | G7: 9.2 | H7: 1 | I7: 1 | J7: 2 | K7: {=_xlfn.IFS(stdsurvey[[#This Row],[phq9_score]]="","Answer Not Provided",stdsurvey[[#This Row],[phq9_score]]<=4,"Minimal",stdsurvey[[#This Row],[phq9_score]]<=9,"Mild",stdsurvey[[#This Row],[phq9_score]]<=14,"Moderate",stdsurvey[[#This Row],[phq9_score]]<=19,"Moderately Severe",stdsurvey[[#This Row],[phq9_score]]<=27,"Severe")} -> Minimal | L7: 10 | M7: {=_xlfn.IFS(stdsurvey[[#This Row],[gad7_score]]="","Answer Not Provided",stdsurvey[[#This Row],[gad7_score]]<=4,"Minimal",stdsurvey[[#This Row],[gad7_score]]<=9,"Mild",stdsurvey[[#This Row],[gad7_score]]<=14,"Moderate",stdsurvey[[#This Row],[gad7_score]]<=21,"Severe")} -> Minimal | N7: 17.1 | O7: {=_xlfn.IFS(stdsurvey[[#This Row],[perceived_stress_scale]]="","Answer Not Provided",stdsurvey[[#This Row],[perceived_stress_scale]]<=13,"Low Stress",stdsurvey[[#This Row],[perceived_stress_scale]]<=26,"Moderate Stress",stdsurvey[[#This Row],[perceived_stress_scale]]<=40,"High Stress")} -> Low Stress | P7: 92.5 | Q7: 5 | R7: {=_xlfn.IFS(stdsurvey[[#This Row],[class_attendance_percent]]<60,"Less than 0%",stdsurvey[[#This Row],[class_attendance_percent]]<70,"60-70 %",stdsurvey[[#This Row],[class_attendance_percent]]<80, "70-80%",stdsurvey[[#This Row],[class_attendance_percent]]<90,"80-90%",TRUE,"More than 90%")} -> More than 90% | S7: No | T7: 3 | U7: Spring | V7: 3.27 | W7: {=_xlfn.IFS( stdsurvey[[#This Row],[daily_screen_time_hours]]<1,"<1 hr", stdsurvey[[#This Row],[daily_screen_time_hours]]<4,"1-4 hrs", stdsurvey[[#This Row],[daily_screen_time_hours]]<8,"4-8 hrs", stdsurvey[[#This Row],[daily_screen_time_hours]]<12,"8-12 hrs", stdsurvey[[#This Row],[daily_screen_time_hours]]<=16,"12-16 hrs", TRUE,">16 hrs" )} -> 8-12 hrs | X7: {=_xlfn.IFS(stdsurvey[[#This Row],[daily_sleep_hours]]<4,"< 4 hrs",stdsurvey[[#This Row],[daily_sleep_hours]]<=6,"4-6 hrs",stdsurvey[[#This Row],[daily_sleep_hours]]<=8,"6-8 hrs",TRUE,"> 8 hrs")} -> 4-6 hrs | Y7: Prefer not to say
A8: STU1004 | B8: 23 | C8: Male | D8: 2 | E8: Humanities | F8: 3.8 | G8: 2 | H8: 6 | I8: 4 | J8: 6 | K8: {=_xlfn.IFS(stdsurvey[[#This Row],[phq9_score]]="","Answer Not Provided",stdsurvey[[#This Row],[phq9_score]]<=4,"Minimal",stdsurvey[[#This Row],[phq9_score]]<=9,"Mild",stdsurvey[[#This Row],[phq9_score]]<=14,"Moderate",stdsurvey[[#This Row],[phq9_score]]<=19,"Moderately Severe",stdsurvey[[#This Row],[phq9_score]]<=27,"Severe")} -> Minimal | L8: 9 | M8: {=_xlfn.IFS(stdsurvey[[#This Row],[gad7_score]]="","Answer Not Provided",stdsurvey[[#This Row],[gad7_score]]<=4,"Minimal",stdsurvey[[#This Row],[gad7_score]]<=9,"Mild",stdsurvey[[#This Row],[gad7_score]]<=14,"Moderate",stdsurvey[[#This Row],[gad7_score]]<=21,"Severe")} -> Mild | N8: 25.2 | O8: {=_xlfn.IFS(stdsurvey[[#This Row],[perceived_stress_scale]]="","Answer Not Provided",stdsurvey[[#This Row],[perceived_stress_scale]]<=13,"Low Stress",stdsurvey[[#This Row],[perceived_stress_scale]]<=26,"Moderate Stress",stdsurvey[[#This Row],[perceived_stress_scale]]<=40,"High Stress")} -> Low Stress | P8: 86.5 | Q8: 3 | R8: {=_xlfn.IFS(stdsurvey[[#This Row],[class_attendance_percent]]<60,"Less than 0%",stdsurvey[[#This Row],[class_attendance_percent]]<70,"60-70 %",stdsurvey[[#This Row],[class_attendance_percent]]<80, "70-80%",stdsurvey[[#This Row],[class_attendance_percent]]<90,"80-90%",TRUE,"More than 90%")} -> 80-90% | S8: Yes | T8: 2 | U8: Spring | V8: 3.09 | W8: {=_xlfn.IFS( stdsurvey[[#This Row],[daily_screen_time_hours]]<1,"<1 hr", stdsurvey[[#This Row],[daily_screen_time_hours]]<4,"1-4 hrs", stdsurvey[[#This Row],[daily_screen_time_hours]]<8,"4-8 hrs", stdsurvey[[#This Row],[daily_screen_time_hours]]<12,"8-12 hrs", stdsurvey[[#This Row],[daily_screen_time_hours]]<=16,"12-16 hrs", TRUE,">16 hrs" )} -> 1-4 hrs | X8: {=_xlfn.IFS(stdsurvey[[#This Row],[daily_sleep_hours]]<4,"< 4 hrs",stdsurvey[[#This Row],[daily_sleep_hours]]<=6,"4-6 hrs",stdsurvey[[#This Row],[daily_sleep_hours]]<=8,"6-8 hrs",TRUE,"> 8 hrs")} -> < 4 hrs | Y8: Male
A9: STU1005 | B9: 17 | C9: Female | D9: 5 | E9: Arts | F9: 5.8 | G9: 4.1 | H9: 0 | I9: 10 | J9: 6 | K9: {=_xlfn.IFS(stdsurvey[[#This Row],[phq9_score]]="","Answer Not Provided",stdsurvey[[#This Row],[phq9_score]]<=4,"Minimal",stdsurvey[[#This Row],[phq9_score]]<=9,"Mild",stdsurvey[[#This Row],[phq9_score]]<=14,"Moderate",stdsurvey[[#This Row],[phq9_score]]<=19,"Moderately Severe",stdsurvey[[#This Row],[phq9_score]]<=27,"Severe")} -> Moderate | L9: 15 | M9: {=_xlfn.IFS(stdsurvey[[#This Row],[gad7_score]]="","Answer Not Provided",stdsurvey[[#This Row],[gad7_score]]<=4,"Minimal",stdsurvey[[#This Row],[gad7_score]]<=9,"Mild",stdsurvey[[#This Row],[gad7_score]]<=14,"Moderate",stdsurvey[[#This Row],[gad7_score]]<=21,"Severe")} -> Mild | N9: 4.6 | O9: {=_xlfn.IFS(stdsurvey[[#This Row],[perceived_stress_scale]]="","Answer Not Provided",stdsurvey[[#This Row],[perceived_stress_scale]]<=13,"Low Stress",stdsurvey[[#This Row],[perceived_stress_scale]]<=26,"Moderate Stress",stdsurvey[[#This Row],[perceived_stress_scale]]<=40,"High Stress")} -> Moderate Stress | P9: 83.9 | Q9: 5 | R9: {=_xlfn.IFS(stdsurvey[[#This Row],[class_attendance_percent]]<60,"Less than 0%",stdsurvey[[#This Row],[class_attendance_percent]]<70,"60-70 %",stdsurvey[[#This Row],[class_attendance_percent]]<80, "70-80%",stdsurvey[[#This Row],[class_attendance_percent]]<90,"80-90%",TRUE,"More than 90%")} -> 80-90% | S9: Yes | T9: 3 | U9: Spring | V9: 2.28 | W9: {=_xlfn.IFS( stdsurvey[[#This Row],[daily_screen_time_hours]]<1,"<1 hr", stdsurvey[[#This Row],[daily_screen_time_hours]]<4,"1-4 hrs", stdsurvey[[#This Row],[daily_screen_time_hours]]<8,"4-8 hrs", stdsurvey[[#This Row],[daily_screen_time_hours]]<12,"8-12 hrs", stdsurvey[[#This Row],[daily_screen_time_hours]]<=16,"12-16 hrs", TRUE,">16 hrs" )} -> 4-8 hrs | X9: {=_xlfn.IFS(stdsurvey[[#This Row],[daily_sleep_hours]]<4,"< 4 hrs",stdsurvey[[#This Row],[daily_sleep_hours]]<=6,"4-6 hrs",stdsurvey[[#This Row],[daily_sleep_hours]]<=8,"6-8 hrs",TRUE,"> 8 hrs")} -> 4-6 hrs | Y9: Female
A10: STU1006 | B10: 19 | C10: Female | D10: 2 | E10: Business | F10: 5.2 | G10: 5.8 | H10: 4 | I10: 5 | J10: 5 | K10: {=_xlfn.IFS(stdsurvey[[#This Row],[phq9_score]]="","Answer Not Provided",stdsurvey[[#This Row],[phq9_score]]<=4,"Minimal",stdsurvey[[#This Row],[phq9_score]]<=9,"Mild",stdsurvey[[#This Row],[phq9_score]]<=14,"Moderate",stdsurvey[[#This Row],[phq9_score]]<=19,"Moderately Severe",stdsurvey[[#This Row],[phq9_score]]<=27,"Severe")} -> Mild | L10: 8 | M10: {=_xlfn.IFS(stdsurvey[[#This Row],[gad7_score]]="","Answer Not Provided",stdsurvey[[#This Row],[gad7_score]]<=4,"Minimal",stdsurvey[[#This Row],[gad7_score]]<=9,"Mild",stdsurvey[[#This Row],[gad7_score]]<=14,"Moderate",stdsurvey[[#This Row],[gad7_score]]<=21,"Severe")} -> Mild | N10: 12.5 | O10: {=_xlfn.IFS(stdsurvey[[#This Row],[perceived_stress_scale]]="","Answer Not Provided",stdsurvey[[#This Row],[perceived_stress_scale]]<=13,"Low Stress",stdsurvey[[#This Row],[perceived_stress_scale]]<=26,"Moderate Stress",stdsurvey[[#This Row],[perceived_stress_scale]]<=40,"High Stress")} -> Low Stress | P10: 78.4 | Q10: 2 | R10: {=_xlfn.IFS(stdsurvey[[#This Row],[class_attendance_percent]]<60,"Less than 0%",stdsurvey[[#This Row],[class_attendance_percent]]<70,"60-70 %",stdsurvey[[#This Row],[class_attendance_percent]]<80, "70-80%",stdsurvey[[#This Row],[class_attendance_percent]]<90,"80-90%",TRUE,"More than 90%")} -> 70-80% | S10: No | T10: 3 | U10: Spring | V10: 2.69 | W10: {=_xlfn.IFS( stdsurvey[[#This Row],[daily_screen_time_hours]]<1,"<1 hr", stdsurvey[[#This Row],[daily_screen_time_hours]]<4,"1-4 hrs", stdsurvey[[#This Row],[daily_screen_time_hours]]<8,"4-8 hrs", stdsurvey[[#This Row],[daily_screen_time_hours]]<12,"8-12 hrs", stdsurvey[[#This Row],[daily_screen_time_hours]]<=16,"12-16 hrs", TRUE,">16 hrs" )} -> 4-8 hrs | X10: {=_xlfn.IFS(stdsurvey[[#This Row],[daily_sleep_hours]]<4,"< 4 hrs",stdsurvey[[#This Row],[daily_sleep_hours]]<=6,"4-6 hrs",stdsurvey[[#This Row],[daily_sleep_hours]]<=8,"6-8 hrs",TRUE,"> 8 hrs")} -> 4-6 hrs | Y10: Female
A11: STU1007 | B11: 22 | C11: Male | D11: 3 | E11: Humanities | F11: 4.3 | G11: 4.6 | H11: 4 | I11: 3 | J11: 3 | K11: {=_xlfn.IFS(stdsurvey[[#This Row],[phq9_score]]="","Answer Not Provided",stdsurvey[[#This Row],[phq9_score]]<=4,"Minimal",stdsurvey[[#This Row],[phq9_score]]<=9,"Mild",stdsurvey[[#This Row],[phq9_score]]<=14,"Moderate",stdsurvey[[#This Row],[phq9_score]]<=19,"Moderately Severe",stdsurvey[[#This Row],[phq9_score]]<=27,"Severe")} -> Minimal | L11: 5 | M11: {=_xlfn.IFS(stdsurvey[[#This Row],[gad7_score]]="","Answer Not Provided",stdsurvey[[#This Row],[gad7_score]]<=4,"Minimal",stdsurvey[[#This Row],[gad7_score]]<=9,"Mild",stdsurvey[[#This Row],[gad7_score]]<=14,"Moderate",stdsurvey[[#This Row],[gad7_score]]<=21,"Severe")} -> Minimal | N11: 20.8 | O11: {=_xlfn.IFS(stdsurvey[[#This Row],[perceived_stress_scale]]="","Answer Not Provided",stdsurvey[[#This Row],[perceived_stress_scale]]<=13,"Low Stress",stdsurvey[[#This Row],[perceived_stress_scale]]<=26,"Moderate Stress",stdsurvey[[#This Row],[perceived_stress_scale]]<=40,"High Stress")} -> Low Stress | P11: 75.5 | Q11: 4 | R11: {=_xlfn.IFS(stdsurvey[[#This Row],[class_attendance_percent]]<60,"Less than 0%",stdsurvey[[#This Row],[class_attendance_percent]]<70,"60-70 %",stdsurvey[[#This Row],[class_attendance_percent]]<80, "70-80%",stdsurvey[[#This Row],[class_attendance_percent]]<90,"80-90%",TRUE,"More than 90%")} -> 70-80% | S11: No | T11: 3 | U11: Fall | V11: 2.9 | W11: {=_xlfn.IFS( stdsurvey[[#This Row],[daily_screen_time_hours]]<1,"<1 hr", stdsurvey[[#This Row],[daily_screen_time_hours]]<4,"1-4 hrs", stdsurvey[[#This Row],[daily_screen_time_hours]]<8,"4-8 hrs", stdsurvey[[#This Row],[daily_screen_time_hours]]<12,"8-12 hrs", stdsurvey[[#This Row],[daily_screen_time_hours]]<=16,"12-16 hrs", TRUE,">16 hrs" )} -> 4-8 hrs | X11: {=_xlfn.IFS(stdsurvey[[#This Row],[daily_sleep_hours]]<4,"< 4 hrs",stdsurvey[[#This Row],[daily_sleep_hours]]<=6,"4-6 hrs",stdsurvey[[#This Row],[daily_sleep_hours]]<=8,"6-8 hrs",TRUE,"> 8 hrs")} -> 4-6 hrs | Y11: Male
A12: STU1008 | B12: 21 | C12: male | D12: 1 | E12: STEM | F12: 8.3 | G12: 5.3 | H12: 0 | I12: 27 | J12: 19 | K12: {=_xlfn.IFS(stdsurvey[[#This Row],[phq9_score]]="","Answer Not Provided",stdsurvey[[#This Row],[phq9_score]]<=4,"Minimal",stdsurvey[[#This Row],[phq9_score]]<=9,"Mild",stdsurvey[[#This Row],[phq9_score]]<=14,"Moderate",stdsurvey[[#This Row],[phq9_score]]<=19,"Moderately Severe",stdsurvey[[#This Row],[phq9_score]]<=27,"Severe")} -> Severe | L12: 28 | M12: {=_xlfn.IFS(stdsurvey[[#This Row],[gad7_score]]="","Answer Not Provided",stdsurvey[[#This Row],[gad7_score]]<=4,"Minimal",stdsurvey[[#This Row],[gad7_score]]<=9,"Mild",stdsurvey[[#This Row],[gad7_score]]<=14,"Moderate",stdsurvey[[#This Row],[gad7_score]]<=21,"Severe")} -> Severe | N12: 24.6 | O12: {=_xlfn.IFS(stdsurvey[[#This Row],[perceived_stress_scale]]="","Answer Not Provided",stdsurvey[[#This Row],[perceived_stress_scale]]<=13,"Low Stress",stdsurvey[[#This Row],[perceived_stress_scale]]<=26,"Moderate Stress",stdsurvey[[#This Row],[perceived_stress_scale]]<=40,"High Stress")} -> High Stress | P12: 71.2 | Q12: 2 | R12: {=_xlfn.IFS(stdsurvey[[#This Row],[class_attendance_percent]]<60,"Less than 0%",stdsurvey[[#This Row],[class_attendance_percent]]<70,"60-70 %",stdsurvey[[#This Row],[class_attendance_percent]]<80, "70-80%",stdsurvey[[#This Row],[class_attendance_percent]]<90,"80-90%",TRUE,"More than 90%")} -> 70-80% | S12: No | T12: 5 | U12: Fall | W12: {=_xlfn.IFS( stdsurvey[[#This Row],[daily_screen_time_hours]]<1,"<1 hr", stdsurvey[[#This Row],[daily_screen_time_hours]]<4,"1-4 hrs", stdsurvey[[#This Row],[daily_screen_time_hours]]<8,"4-8 hrs", stdsurvey[[#This Row],[daily_screen_time_hours]]<12,"8-12 hrs", stdsurvey[[#This Row],[daily_screen_time_hours]]<=16,"12-16 hrs", TRUE,">16 hrs" )} -> 4-8 hrs | X12: {=_xlfn.IFS(stdsurvey[[#This Row],[daily_sleep_hours]]<4,"< 4 hrs",stdsurvey[[#This Row],[daily_sleep_hours]]<=6,"4-6 hrs",stdsurvey[[#This Row],[daily_sleep_hours]]<=8,"6-8 hrs",TRUE,"> 8 hrs")} -> > 8 hrs | Y12: Male
A13: STU1009 | B13: 21 | C13: Female | D13: 2 | E13: STEM | F13: 6.8 | G13: 2.3 | H13: 1 | I13: 7 | J13: 8 | K13: {=_xlfn.IFS(stdsurvey[[#This Row],[phq9_score]]="","Answer Not Provided",stdsurvey[[#This Row],[phq9_score]]<=4,"Minimal",stdsurvey[[#This Row],[phq9_score]]<=9,"Mild",stdsurvey[[#This Row],[phq9_score]]<=14,"Moderate",stdsurvey[[#This Row],[phq9_score]]<=19,"Moderately Severe",stdsurvey[[#This Row],[phq9_score]]<=27,"Severe")} -> Mild | L13: 12 | M13: {=_xlfn.IFS(stdsurvey[[#This Row],[gad7_score]]="","Answer Not Provided",stdsurvey[[#This Row],[gad7_score]]<=4,"Minimal",stdsurvey[[#This Row],[gad7_score]]<=9,"Mild",stdsurvey[[#This Row],[gad7_score]]<=14,"Moderate",stdsurvey[[#This Row],[gad7_score]]<=21,"Severe")} -> Mild | N13: 32.7 | O13: {=_xlfn.IFS(stdsurvey[[#This Row],[perceived_stress_scale]]="","Answer Not Provided",stdsurvey[[#This Row],[perceived_stress_scale]]<=13,"Low Stress",stdsurvey[[#This Row],[perceived_stress_scale]]<=26,"Moderate Stress",stdsurvey[[#This Row],[perceived_stress_scale]]<=40,"High Stress")} -> Low Stress | P13: 96 | Q13: 5 | R13: {=_xlfn.IFS(stdsurvey[[#This Row],[class_attendance_percent]]<60,"Less than 0%",stdsurvey[[#This Row],[class_attendance_percent]]<70,"60-70 %",stdsurvey[[#This Row],[class_attendance_percent]]<80, "70-80%",stdsurvey[[#This Row],[class_attendance_percent]]<90,"80-90%",TRUE,"More than 90%")} -> More than 90% | S13: No | T13: 4 | U13: Spring | V13: 3.18 | W13: {=_xlfn.IFS( stdsurvey[[#This Row],[daily_screen_time_hours]]<1,"<1 hr", stdsurvey[[#This Row],[daily_screen_time_hours]]<4,"1-4 hrs", stdsurvey[[#This Row],[daily_screen_time_hours]]<8,"4-8 hrs", stdsurvey[[#This Row],[daily_screen_time_hours]]<12,"8-12 hrs", stdsurvey[[#This Row],[daily_screen_time_hours]]<=16,"12-16 hrs", TRUE,">16 hrs" )} -> 1-4 hrs | X13: {=_xlfn.IFS(stdsurvey[[#This Row],[daily_sleep_hours]]<4,"< 4 hrs",stdsurvey[[#This Row],[daily_sleep_hours]]<=6,"4-6 hrs",stdsurvey[[#This Row],[daily_sleep_hours]]<=8,"6-8 hrs",TRUE,"> 8 hrs")} -> 6-8 hrs | Y13: Female
A14: STU1010 | B14: 20 | C14: Female | D14: 4 | E14: STEM | F14: 6.6 | G14: 5.9 | H14: 2 | I14: 6 | J14: 7 | K14: {=_xlfn.IFS(stdsurvey[[#This Row],[phq9_score]]="","Answer Not Provided",stdsurvey[[#This Row],[phq9_score]]<=4,"Minimal",stdsurvey[[#This Row],[phq9_score]]<=9,"Mild",stdsurvey[[#This Row],[phq9_score]]<=14,"Moderate",stdsurvey[[#This Row],[phq9_score]]<=19,"Moderately Severe",stdsurvey[[#This Row],[phq9_score]]<=27,"Severe")} -> Mild | L14: 13 | M14: {=_xlfn.IFS(stdsurvey[[#This Row],[gad7_score]]="","Answer Not Provided",stdsurvey[[#This Row],[gad7_score]]<=4,"Minimal",stdsurvey[[#This Row],[gad7_score]]<=9,"Mild",stdsurvey[[#This Row],[gad7_score]]<=14,"Moderate",stdsurvey[[#This Row],[gad7_score]]<=21,"Severe")} -> Mild | N14: 20.8 | O14: {=_xlfn.IFS(stdsurvey[[#This Row],[perceived_stress_scale]]="","Answer Not Provided",stdsurvey[[#This Row],[perceived_stress_scale]]<=13,"Low Stress",stdsurvey[[#This Row],[perceived_stress_scale]]<=26,"Moderate Stress",stdsurvey[[#This Row],[perceived_stress_scale]]<=40,"High Stress")} -> Low Stress | P14: 97.1 | Q14: 5 | R14: {=_xlfn.IFS(stdsurvey[[#This Row],[class_attendance_percent]]<60,"Less than 0%",stdsurvey[[#This Row],[class_attendance_percent]]<70,"60-70 %",stdsurvey[[#This Row],[class_attendance_percent]]<80, "70-80%",stdsurvey[[#This Row],[class_attendance_percent]]<90,"80-90%",TRUE,"More than 90%")} -> More than 90% | S14: No | T14: 4 | U14: Fall | V14: 3.11 | W14: {=_xlfn.IFS( stdsurvey[[#This Row],[daily_screen_time_hours]]<1,"<1 hr", stdsurvey[[#This Row],[daily_screen_time_hours]]<4,"1-4 hrs", stdsurvey[[#This Row],[daily_screen_time_hours]]<8,"4-8 hrs", stdsurvey[[#This Row],[daily_screen_time_hours]]<12,"8-12 hrs", stdsurvey[[#This Row],[daily_screen_time_hours]]<=16,"12-16 hrs", TRUE,">16 hrs" )} -> 4-8 hrs | X14: {=_xlfn.IFS(stdsurvey[[#This Row],[daily_sleep_hours]]<4,"< 4 hrs",stdsurvey[[#This Row],[daily_sleep_hours]]<=6,"4-6 hrs",stdsurvey[[#This Row],[daily_sleep_hours]]<=8,"6-8 hrs",TRUE,"> 8 hrs")} -> 6-8 hrs | Y14: Female
A15: STU1011 | B15: 23 | C15: Male | D15: 3 | E15: STEM | F15: 6.1 | G15: 1.1 | H15: 5 | I15: 8 | J15: 6 | K15: {=_xlfn.IFS(stdsurvey[[#This Row],[phq9_score]]="","Answer Not Provided",stdsurvey[[#This Row],[phq9_score]]<=4,"Minimal",stdsurvey[[#This Row],[phq9_score]]<=9,"Mild",stdsurvey[[#This Row],[phq9_score]]<=14,"Moderate",stdsurvey[[#This Row],[phq9_score]]<=19,"Moderately Severe",stdsurvey[[#This Row],[phq9_score]]<=27,"Severe")} -> Mild | L15: 7 | M15: {=_xlfn.IFS(stdsurvey[[#This Row],[gad7_score]]="","Answer Not Provided",stdsurvey[[#This Row],[gad7_score]]<=4,"Minimal",stdsurvey[[#This Row],[gad7_score]]<=9,"Mild",stdsurvey[[#This Row],[gad7_score]]<=14,"Moderate",stdsurvey[[#This Row],[gad7_score]]<=21,"Severe")} -> Mild | N15: 31.6 | O15: {=_xlfn.IFS(stdsurvey[[#This Row],[perceived_stress_scale]]="","Answer Not Provided",stdsurvey[[#This Row],[perceived_stress_scale]]<=13,"Low Stress",stdsurvey[[#This Row],[perceived_stress_scale]]<=26,"Moderate Stress",stdsurvey[[#This Row],[perceived_stress_scale]]<=40,"High Stress")} -> Low Stress | P15: 65.6 | Q15: 3 | R15: {=_xlfn.IFS(stdsurvey[[#This Row],[class_attendance_percent]]<60,"Less than 0%",stdsurvey[[#This Row],[class_attendance_percent]]<70,"60-70 %",stdsurvey[[#This Row],[class_attendance_percent]]<80, "70-80%",stdsurvey[[#This Row],[class_attendance_percent]]<90,"80-90%",TRUE,"More than 90%")} -> 60-70 % | S15: No | T15: 3 | U15: Spring | V15: 2.85 | W15: {=_xlfn.IFS( stdsurvey[[#This Row],[daily_screen_time_hours]]<1,"<1 hr", stdsurvey[[#This Row],[daily_screen_time_hours]]<4,"1-4 hrs", stdsurvey[[#This Row],[daily_screen_time_hours]]<8,"4-8 hrs", stdsurvey[[#This Row],[daily_screen_time_hours]]<12,"8-12 hrs", stdsurvey[[#This Row],[daily_screen_time_hours]]<=16,"12-16 hrs", TRUE,">16 hrs" )} -> 1-4 hrs | X15: {=_xlfn.IFS(stdsurvey[[#This Row],[daily_sleep_hours]]<4,"< 4 hrs",stdsurvey[[#This Row],[daily_sleep_hours]]<=6,"4-6 hrs",stdsurvey[[#This Row],[daily_sleep_hours]]<=8,"6-8 hrs",TRUE,"> 8 hrs")} -> 6-8 hrs | Y15: Male
A16: STU1012 | B16: 23 | C16: Male | D16: 2 | E16: Arts | F16: 5.2 | G16: 9.1 | H16: 3 | I16: 4 | J16: 5 | K16: {=_xlfn.IFS(stdsurvey[[#This Row],[phq9_score]]="","Answer Not Provided",stdsurvey[[#This Row],[phq9_score]]<=4,"Minimal",stdsurvey[[#This Row],[phq9_score]]<=9,"Mild",stdsurvey[[#This Row],[phq9_score]]<=14,"Moderate",stdsurvey[[#This Row],[phq9_score]]<=19,"Moderately Severe",stdsurvey[[#This Row],[phq9_score]]<=27,"Severe")} -> Minimal | L16: 10 | M16: {=_xlfn.IFS(stdsurvey[[#This Row],[gad7_score]]="","Answer Not Provided",stdsurvey[[#This Row],[gad7_score]]<=4,"Minimal",stdsurvey[[#This Row],[gad7_score]]<=9,"Mild",stdsurvey[[#This Row],[gad7_score]]<=14,"Moderate",stdsurvey[[#This Row],[gad7_score]]<=21,"Severe")} -> Mild | N16: 11.5 | O16: {=_xlfn.IFS(stdsurvey[[#This Row],[perceived_stress_scale]]="","Answer Not Provided",stdsurvey[[#This Row],[perceived_stress_scale]]<=13,"Low Stress",stdsurvey[[#This Row],[perceived_stress_scale]]<=26,"Moderate Stress",stdsurvey[[#This Row],[perceived_stress_scale]]<=40,"High Stress")} -> Low Stress | P16: 89 | Q16: 3 | R16: {=_xlfn.IFS(stdsurvey[[#This Row],[class_attendance_percent]]<60,"Less than 0%",stdsurvey[[#This Row],[class_attendance_percent]]<70,"60-70 %",stdsurvey[[#This Row],[class_attendance_percent]]<80, "70-80%",stdsurvey[[#This Row],[class_attendance_percent]]<90,"80-90%",TRUE,"More than 90%")} -> 80-90% | S16: Yes | T16: 5 | U16: Spring | V16: 2.43 | W16: {=_xlfn.IFS( stdsurvey[[#This Row],[daily_screen_time_hours]]<1,"<1 hr", stdsurvey[[#This Row],[daily_screen_time_hours]]<4,"1-4 hrs", stdsurvey[[#This Row],[daily_screen_time_hours]]<8,"4-8 hrs", stdsurvey[[#This Row],[daily_screen_time_hours]]<12,"8-12 hrs", stdsurvey[[#This Row],[daily_screen_time_hours]]<=16,"12-16 hrs", TRUE,">16 hrs" )} -> 8-12 hrs | X16: {=_xlfn.IFS(stdsurvey[[#This Row],[daily_sleep_hours]]<4,"< 4 hrs",stdsurvey[[#This Row],[daily_sleep_hours]]<=6,"4-6 hrs",stdsurvey[[#This Row],[daily_sleep_hours]]<=8,"6-8 hrs",TRUE,"> 8 hrs")} -> 4-6 hrs | Y16: Male
A17: STU1013 | B17: 22 | C17: female | D17: 5 | E17: Business | F17: 8.2 | G17: 1 | H17: 3 | K17: {=_xlfn.IFS(stdsurvey[[#This Row],[phq9_score]]="","Answer Not Provided",stdsurvey[[#This Row],[phq9_score]]<=4,"Minimal",stdsurvey[[#This Row],[phq9_score]]<=9,"Mild",stdsurvey[[#This Row],[phq9_score]]<=14,"Moderate",stdsurvey[[#This Row],[phq9_score]]<=19,"Moderately Severe",stdsurvey[[#This Row],[phq9_score]]<=27,"Severe")} -> Answer Not Provided | L17: 21 | M17: {=_xlfn.IFS(stdsurvey[[#This Row],[gad7_score]]="","Answer Not Provided",stdsurvey[[#This Row],[gad7_score]]<=4,"Minimal",stdsurvey[[#This Row],[gad7_score]]<=9,"Mild",stdsurvey[[#This Row],[gad7_score]]<=14,"Moderate",stdsurvey[[#This Row],[gad7_score]]<=21,"Severe")} -> Answer Not Provided | N17: 24.5 | O17: {=_xlfn.IFS(stdsurvey[[#This Row],[perceived_stress_scale]]="","Answer Not Provided",stdsurvey[[#This Row],[perceived_stress_scale]]<=13,"Low Stress",stdsurvey[[#This Row],[perceived_stress_scale]]<=26,"Moderate Stress",stdsurvey[[#This Row],[perceived_stress_scale]]<=40,"High Stress")} -> Moderate Stress | P17: 71.8 | Q17: 4 | R17: {=_xlfn.IFS(stdsurvey[[#This Row],[class_attendance_percent]]<60,"Less than 0%",stdsurvey[[#This Row],[class_attendance_percent]]<70,"60-70 %",stdsurvey[[#This Row],[class_attendance_percent]]<80, "70-80%",stdsurvey[[#This Row],[class_attendance_percent]]<90,"80-90%",TRUE,"More than 90%")} -> 70-80% | S17: No | T17: 2 | U17: Spring | V17: 3.13 | W17: {=_xlfn.IFS( stdsurvey[[#This Row],[daily_screen_time_hours]]<1,"<1 hr", stdsurvey[[#This Row],[daily_screen_time_hours]]<4,"1-4 hrs", stdsurvey[[#This Row],[daily_screen_time_hours]]<8,"4-8 hrs", stdsurvey[[#This Row],[daily_screen_time_hours]]<12,"8-12 hrs", stdsurvey[[#This Row],[daily_screen_time_hours]]<=16,"12-16 hrs", TRUE,">16 hrs" )} -> 1-4 hrs | X17: {=_xlfn.IFS(stdsurvey[[#This Row],[daily_sleep_hours]]<4,"< 4 hrs",stdsurvey[[#This Row],[daily_sleep_hours]]<=6,"4-6 hrs",stdsurvey[[#This Row],[daily_sleep_hours]]<=8,"6-8 hrs",TRUE,"> 8 hrs")} -> > 8 hrs | Y17: Female
A18: STU1014 | B18: 24 | C18: Male | D18: 4 | E18: Health Sciences | F18: 6.4 | G18: 2.9 | H18: 4 | I18: 7 | J18: 5 | K18: {=_xlfn.IFS(stdsurvey[[#This Row],[phq9_score]]="","Answer Not Provided",stdsurvey[[#This Row],[phq9_score]]<=4,"Minimal",stdsurvey[[#This Row],[phq9_score]]<=9,"Mild",stdsurvey[[#This Row],[phq9_score]]<=14,"Moderate",stdsurvey[[#This Row],[phq9_score]]<=19,"Moderately Severe",stdsurvey[[#This Row],[phq9_score]]<=27,"Severe")} -> Mild | L18: 15 | M18: {=_xlfn.IFS(stdsurvey[[#This Row],[gad7_score]]="","Answer Not Provided",stdsurvey[[#This Row],[gad7_score]]<=4,"Minimal",stdsurvey[[#This Row],[gad7_score]]<=9,"Mild",stdsurvey[[#This Row],[gad7_score]]<=14,"Moderate",stdsurvey[[#This Row],[gad7_score]]<=21,"Severe")} -> Mild | N18: 11.4 | O18: {=_xlfn.IFS(stdsurvey[[#This Row],[perceived_stress_scale]]="","Answer Not Provided",stdsurvey[[#This Row],[perceived_stress_scale]]<=13,"Low Stress",stdsurvey[[#This Row],[perceived_stress_scale]]<=26,"Moderate Stress",stdsurvey[[#This Row],[perceived_stress_scale]]<=40,"High Stress")} -> Moderate Stress | P18: 86.2 | Q18: 3 | R18: {=_xlfn.IFS(stdsurvey[[#This Row],[class_attendance_percent]]<60,"Less than 0%",stdsurvey[[#This Row],[class_attendance_percent]]<70,"60-70 %",stdsurvey[[#This Row],[class_attendance_percent]]<80, "70-80%",stdsurvey[[#This Row],[class_attendance_percent]]<90,"80-90%",TRUE,"More than 90%")} -> 80-90% | S18: No | T18: 2 | U18: Spring | V18: 3.1 | W18: {=_xlfn.IFS( stdsurvey[[#This Row],[daily_screen_time_hours]]<1,"<1 hr", stdsurvey[[#This Row],[daily_screen_time_hours]]<4,"1-4 hrs", stdsurvey[[#This Row],[daily_screen_time_hours]]<8,"4-8 hrs", stdsurvey[[#This Row],[daily_screen_time_hours]]<12,"8-12 hrs", stdsurvey[[#This Row],[daily_screen_time_hours]]<=16,"12-16 hrs", TRUE,">16 hrs" )} -> 1-4 hrs | X18: {=_xlfn.IFS(stdsurvey[[#This Row],[daily_sleep_hours]]<4,"< 4 hrs",stdsurvey[[#This Row],[daily_sleep_hours]]<=6,"4-6 hrs",stdsurvey[[#This Row],[daily_sleep_hours]]<=8,"6-8 hrs",TRUE,"> 8 hrs")} -> 6-8 hrs | Y18: Male
A19: STU1015 | B19: 22 | C19: Male | D19: 2 | E19: Social Sciences | F19: 7.6 | G19: 4.1 | H19: 4 | I19: 6 | J19: 6 | K19: {=_xlfn.IFS(stdsurvey[[#This Row],[phq9_score]]="","Answer Not Provided",stdsurvey[[#This Row],[phq9_score]]<=4,"Minimal",stdsurvey[[#This Row],[phq9_score]]<=9,"Mild",stdsurvey[[#This Row],[phq9_score]]<=14,"Moderate",stdsurvey[[#This Row],[phq9_score]]<=19,"Moderately Severe",stdsurvey[[#This Row],[phq9_score]]<=27,"Severe")} -> Mild | L19: 10 | M19: {=_xlfn.IFS(stdsurvey[[#This Row],[gad7_score]]="","Answer Not Provided",stdsurvey[[#This Row],[gad7_score]]<=4,"Minimal",stdsurvey[[#This Row],[gad7_score]]<=9,"Mild",stdsurvey[[#This Row],[gad7_score]]<=14,"Moderate",stdsurvey[[#This Row],[gad7_score]]<=21,"Severe")} -> Mild | N19: 18.9 | O19: {=_xlfn.IFS(stdsurvey[[#This Row],[perceived_stress_scale]]="","Answer Not Provided",stdsurvey[[#This Row],[perceived_stress_scale]]<=13,"Low Stress",stdsurvey[[#This Row],[perceived_stress_scale]]<=26,"Moderate Stress",stdsurvey[[#This Row],[perceived_stress_scale]]<=40,"High Stress")} -> Low Stress | P19: 75.7 | Q19: 4 | R19: {=_xlfn.IFS(stdsurvey[[#This Row],[class_attendance_percent]]<60,"Less than 0%",stdsurvey[[#This Row],[class_attendance_percent]]<70,"60-70 %",stdsurvey[[#This Row],[class_attendance_percent]]<80, "70-80%",stdsurvey[[#This Row],[class_attendance_percent]]<90,"80-90%",TRUE,"More than 90%")} -> 70-80% | S19: No | T19: 1 | U19: Spring | V19: 4.1 | W19: {=_xlfn.IFS( stdsurvey[[#This Row],[daily_screen_time_hours]]<1,"<1 hr", stdsurvey[[#This Row],[daily_screen_time_hours]]<4,"1-4 hrs", stdsurvey[[#This Row],[daily_screen_time_hours]]<8,"4-8 hrs", stdsurvey[[#This Row],[daily_screen_time_hours]]<12,"8-12 hrs", stdsurvey[[#This Row],[daily_screen_time_hours]]<=16,"12-16 hrs", TRUE,">16 hrs" )} -> 4-8 hrs | X19: {=_xlfn.IFS(stdsurvey[[#This Row],[daily_sleep_hours]]<4,"< 4 hrs",stdsurvey[[#This Row],[daily_sleep_hours]]<=6,"4-6 hrs",stdsurvey[[#This Row],[daily_sleep_hours]]<=8,"6-8 hrs",TRUE,"> 8 hrs")} -> 6-8 hrs | Y19: Male
A20: STU1016 | B20: 20 | C20: Male | D20: 3 | E20: STEM | F20: 5.5 | G20: 8.8 | H20: 3 | I20: 27 | J20: 19 | K20: {=_xlfn.IFS(stdsurvey[[#This Row],[phq9_score]]="","Answer Not Provided",stdsurvey[[#This Row],[phq9_score]]<=4,"Minimal",stdsurvey[[#This Row],[phq9_score]]<=9,"Mild",stdsurvey[[#This Row],[phq9_score]]<=14,"Moderate",stdsurvey[[#This Row],[phq9_score]]<=19,"Moderately Severe",stdsurvey[[#This Row],[phq9_score]]<=27,"Severe")} -> Severe | L20: 27 | M20: {=_xlfn.IFS(stdsurvey[[#This Row],[gad7_score]]="","Answer Not Provided",stdsurvey[[#This Row],[gad7_score]]<=4,"Minimal",stdsurvey[[#This Row],[gad7_score]]<=9,"Mild",stdsurvey[[#This Row],[gad7_score]]<=14,"Moderate",stdsurvey[[#This Row],[gad7_score]]<=21,"Severe")} -> Severe | N20: 1.5 | O20: {=_xlfn.IFS(stdsurvey[[#This Row],[perceived_stress_scale]]="","Answer Not Provided",stdsurvey[[#This Row],[perceived_stress_scale]]<=13,"Low Stress",stdsurvey[[#This Row],[perceived_stress_scale]]<=26,"Moderate Stress",stdsurvey[[#This Row],[perceived_stress_scale]]<=40,"High Stress")} -> High Stress | P20: 97.8 | R20: {=_xlfn.IFS(stdsurvey[[#This Row],[class_attendance_percent]]<60,"Less than 0%",stdsurvey[[#This Row],[class_attendance_percent]]<70,"60-70 %",stdsurvey[[#This Row],[class_attendance_percent]]<80, "70-80%",stdsurvey[[#This Row],[class_attendance_percent]]<90,"80-90%",TRUE,"More than 90%")} -> More than 90% | S20: No | T20: 3 | U20: Summer | V20: 2.37 | W20: {=_xlfn.IFS( stdsurvey[[#This Row],[daily_screen_time_hours]]<1,"<1 hr", stdsurvey[[#This Row],[daily_screen_time_hours]]<4,"1-4 hrs", stdsurvey[[#This Row],[daily_screen_time_hours]]<8,"4-8 hrs", stdsurvey[[#This Row],[daily_screen_time_hours]]<12,"8-12 hrs", stdsurvey[[#This Row],[daily_screen_time_hours]]<=16,"12-16 hrs", TRUE,">16 hrs" )} -> 8-12 hrs | X20: {=_xlfn.IFS(stdsurvey[[#This Row],[daily_sleep_hours]]<4,"< 4 hrs",stdsurvey[[#This Row],[daily_sleep_hours]]<=6,"4-6 hrs",stdsurvey[[#This Row],[daily_sleep_hours]]<=8,"6-8 hrs",TRUE,"> 8 hrs")} -> 4-6 hrs | Y20: Male
A21: STU1017 | B21: 22 | C21: Female | D21: 3 | E21: STEM | F21: 5.9 | G21: 2 | H21: 3 | I21: 4 | J21: 4 | K21: {=_xlfn.IFS(stdsurvey[[#This Row],[phq9_score]]="","Answer Not Provided",stdsurvey[[#This Row],[phq9_score]]<=4,"Minimal",stdsurvey[[#This Row],[phq9_score]]<=9,"Mild",stdsurvey[[#This Row],[phq9_score]]<=14,"Moderate",stdsurvey[[#This Row],[phq9_score]]<=19,"Moderately Severe",stdsurvey[[#This Row],[phq9_score]]<=27,"Severe")} -> Minimal | L21: 11 | M21: {=_xlfn.IFS(stdsurvey[[#This Row],[gad7_score]]="","Answer Not Provided",stdsurvey[[#This Row],[gad7_score]]<=4,"Minimal",stdsurvey[[#This Row],[gad7_score]]<=9,"Mild",stdsurvey[[#This Row],[gad7_score]]<=14,"Moderate",stdsurvey[[#This Row],[gad7_score]]<=21,"Severe")} -> Minimal | N21: 15.4 | O21: {=_xlfn.IFS(stdsurvey[[#This Row],[perceived_stress_scale]]="","Answer Not Provided",stdsurvey[[#This Row],[perceived_stress_scale]]<=13,"Low Stress",stdsurvey[[#This Row],[perceived_stress_scale]]<=26,"Moderate Stress",stdsurvey[[#This Row],[perceived_stress_scale]]<=40,"High Stress")} -> Low Stress | P21: 75.3 | Q21: 3 | R21: {=_xlfn.IFS(stdsurvey[[#This Row],[class_attendance_percent]]<60,"Less than 0%",stdsurvey[[#This Row],[class_attendance_percent]]<70,"60-70 %",stdsurvey[[#This Row],[class_attendance_percent]]<80, "70-80%",stdsurvey[[#This Row],[class_attendance_percent]]<90,"80-90%",TRUE,"More than 90%")} -> 70-80% | S21: Yes | T21: 3 | U21: Fall | V21: 3.37 | W21: {=_xlfn.IFS( stdsurvey[[#This Row],[daily_screen_time_hours]]<1,"<1 hr", stdsurvey[[#This Row],[daily_screen_time_hours]]<4,"1-4 hrs", stdsurvey[[#This Row],[daily_screen_time_hours]]<8,"4-8 hrs", stdsurvey[[#This Row],[daily_screen_time_hours]]<12,"8-12 hrs", stdsurvey[[#This Row],[daily_screen_time_hours]]<=16,"12-16 hrs", TRUE,">16 hrs" )} -> 1-4 hrs | X21: {=_xlfn.IFS(stdsurvey[[#This Row],[daily_sleep_hours]]<4,"< 4 hrs",stdsurvey[[#This Row],[daily_sleep_hours]]<=6,"4-6 hrs",stdsurvey[[#This Row],[daily_sleep_hours]]<=8,"6-8 hrs",TRUE,"> 8 hrs")} -> 4-6 hrs | Y21: Female
A22: STU1018 | B22: 19 | C22: Female | D22: 3 | E22: Health Sciences | F22: 4.6 | G22: 7.3 | H22: 4 | I22: 3 | J22: 1 | K22: {=_xlfn.IFS(stdsurvey[[#This Row],[phq9_score]]="","Answer Not Provided",stdsurvey[[#This Row],[phq9_score]]<=4,"Minimal",stdsurvey[[#This Row],[phq9_score]]<=9,"Mild",stdsurvey[[#This Row],[phq9_score]]<=14,"Moderate",stdsurvey[[#This Row],[phq9_score]]<=19,"Moderately Severe",stdsurvey[[#This Row],[phq9_score]]<=27,"Severe")} -> Minimal | L22: 1 | M22: {=_xlfn.IFS(stdsurvey[[#This Row],[gad7_score]]="","Answer Not Provided",stdsurvey[[#This Row],[gad7_score]]<=4,"Minimal",stdsurvey[[#This Row],[gad7_score]]<=9,"Mild",stdsurvey[[#This Row],[gad7_score]]<=14,"Moderate",stdsurvey[[#This Row],[gad7_score]]<=21,"Severe")} -> Minimal | N22: 23.7 | O22: {=_xlfn.IFS(stdsurvey[[#This Row],[perceived_stress_scale]]="","Answer Not Provided",stdsurvey[[#This Row],[perceived_stress_scale]]<=13,"Low Stress",stdsurvey[[#This Row],[perceived_stress_scale]]<=26,"Moderate Stress",stdsurvey[[#This Row],[perceived_stress_scale]]<=40,"High Stress")} -> Low Stress | P22: 85.9 | Q22: 2 | R22: {=_xlfn.IFS(stdsurvey[[#This Row],[class_attendance_percent]]<60,"Less than 0%",stdsurvey[[#This Row],[class_attendance_percent]]<70,"60-70 %",stdsurvey[[#This Row],[class_attendance_percent]]<80, "70-80%",stdsurvey[[#This Row],[class_attendance_percent]]<90,"80-90%",TRUE,"More than 90%")} -> 80-90% | S22: Yes | T22: 4 | U22: Spring | V22: 2.99 | W22: {=_xlfn.IFS( stdsurvey[[#This Row],[daily_screen_time_hours]]<1,"<1 hr", stdsurvey[[#This Row],[daily_screen_time_hours]]<4,"1-4 hrs", stdsurvey[[#This Row],[daily_screen_time_hours]]<8,"4-8 hrs", stdsurvey[[#This Row],[daily_screen_time_hours]]<12,"8-12 hrs", stdsurvey[[#This Row],[daily_screen_time_hours]]<=16,"12-16 hrs", TRUE,">16 hrs" )} -> 4-8 hrs | X22: {=_xlfn.IFS(stdsurvey[[#This Row],[daily_sleep_hours]]<4,"< 4 hrs",stdsurvey[[#This Row],[daily_sleep_hours]]<=6,"4-6 hrs",stdsurvey[[#This Row],[daily_sleep_hours]]<=8,"6-8 hrs",TRUE,"> 8 hrs")} -> 4-6 hrs | Y22: Female
A23: STU1019 | B23: 23 | C23: Female | D23: 2 | E23: STEM | F23: 4.5 | G23: 1 | H23: 2 | I23: 7 | J23: 9 | K23: {=_xlfn.IFS(stdsurvey[[#This Row],[phq9_score]]="","Answer Not Provided",stdsurvey[[#This Row],[phq9_score]]<=4,"Minimal",stdsurvey[[#This Row],[phq9_score]]<=9,"Mild",stdsurvey[[#This Row],[phq9_score]]<=14,"Moderate",stdsurvey[[#This Row],[phq9_score]]<=19,"Moderately Severe",stdsurvey[[#This Row],[phq9_score]]<=27,"Severe")} -> Mild | L23: 17 | M23: {=_xlfn.IFS(stdsurvey[[#This Row],[gad7_score]]="","Answer Not Provided",stdsurvey[[#This Row],[gad7_score]]<=4,"Minimal",stdsurvey[[#This Row],[gad7_score]]<=9,"Mild",stdsurvey[[#This Row],[gad7_score]]<=14,"Moderate",stdsurvey[[#This Row],[gad7_score]]<=21,"Severe")} -> Mild | N23: 11.9 | O23: {=_xlfn.IFS(stdsurvey[[#This Row],[perceived_stress_scale]]="","Answer Not Provided",stdsurvey[[#This Row],[perceived_stress_scale]]<=13,"Low Stress",stdsurvey[[#This Row],[perceived_stress_scale]]<=26,"Moderate Stress",stdsurvey[[#This Row],[perceived_stress_scale]]<=40,"High Stress")} -> Moderate Stress | P23: 92 | Q23: 5 | R23: {=_xlfn.IFS(stdsurvey[[#This Row],[class_attendance_percent]]<60,"Less than 0%",stdsurvey[[#This Row],[class_attendance_percent]]<70,"60-70 %",stdsurvey[[#This Row],[class_attendance_percent]]<80, "70-80%",stdsurvey[[#This Row],[class_attendance_percent]]<90,"80-90%",TRUE,"More than 90%")} -> More than 90% | S23: No | T23: 3 | U23: Fall | V23: 2.78 | W23: {=_xlfn.IFS( stdsurvey[[#This Row],[daily_screen_time_hours]]<1,"<1 hr", stdsurvey[[#This Row],[daily_screen_time_hours]]<4,"1-4 hrs", stdsurvey[[#This Row],[daily_screen_time_hours]]<8,"4-8 hrs", stdsurvey[[#This Row],[daily_screen_time_hours]]<12,"8-12 hrs", stdsurvey[[#This Row],[daily_screen_time_hours]]<=16,"12-16 hrs", TRUE,">16 hrs" )} -> 1-4 hrs | X23: {=_xlfn.IFS(stdsurvey[[#This Row],[daily_sleep_hours]]<4,"< 4 hrs",stdsurvey[[#This Row],[daily_sleep_hours]]<=6,"4-6 hrs",stdsurvey[[#This Row],[daily_sleep_hours]]<=8,"6-8 hrs",TRUE,"> 8 hrs")} -> 4-6 hrs | Y23: Female
A24: STU1020 | B24: 21 | C24: Male | D24: 2 | E24: Arts | F24: 6.4 | G24: 2.8 | H24: 5 | I24: 4 | J24: 3 | K24: {=_xlfn.IFS(stdsurvey[[#This Row],[phq9_score]]="","Answer Not Provided",stdsurvey[[#This Row],[phq9_score]]<=4,"Minimal",stdsurvey[[#This Row],[phq9_score]]<=9,"Mild",stdsurvey[[#This Row],[phq9_score]]<=14,"Moderate",stdsurvey[[#This Row],[phq9_score]]<=19,"Moderately Severe",stdsurvey[[#This Row],[phq9_score]]<=27,"Severe")} -> Minimal | L24: 8 | M24: {=_xlfn.IFS(stdsurvey[[#This Row],[gad7_score]]="","Answer Not Provided",stdsurvey[[#This Row],[gad7_score]]<=4,"Minimal",stdsurvey[[#This Row],[gad7_score]]<=9,"Mild",stdsurvey[[#This Row],[gad7_score]]<=14,"Moderate",stdsurvey[[#This Row],[gad7_score]]<=21,"Severe")} -> Minimal | N24: 17.5 | O24: {=_xlfn.IFS(stdsurvey[[#This Row],[perceived_stress_scale]]="","Answer Not Provided",stdsurvey[[#This Row],[perceived_stress_scale]]<=13,"Low Stress",stdsurvey[[#This Row],[perceived_stress_scale]]<=26,"Moderate Stress",stdsurvey[[#This Row],[perceived_stress_scale]]<=40,"High Stress")} -> Low Stress | P24: 66.7 | Q24: 2 | R24: {=_xlfn.IFS(stdsurvey[[#This Row],[class_attendance_percent]]<60,"Less than 0%",stdsurvey[[#This Row],[class_attendance_percent]]<70,"60-70 %",stdsurvey[[#This Row],[class_attendance_percent]]<80, "70-80%",stdsurvey[[#This Row],[class_attendance_percent]]<90,"80-90%",TRUE,"More than 90%")} -> 60-70 % | S24: No | T24: 1 | U24: Spring | V24: 2.73 | W24: {=_xlfn.IFS( stdsurvey[[#This Row],[daily_screen_time_hours]]<1,"<1 hr", stdsurvey[[#This Row],[daily_screen_time_hours]]<4,"1-4 hrs", stdsurvey[[#This Row],[daily_screen_time_hours]]<8,"4-8 hrs", stdsurvey[[#This Row],[daily_screen_time_hours]]<12,"8-12 hrs", stdsurvey[[#This Row],[daily_screen_time_hours]]<=16,"12-16 hrs", TRUE,">16 hrs" )} -> 1-4 hrs | X24: {=_xlfn.IFS(stdsurvey[[#This Row],[daily_sleep_hours]]<4,"< 4 hrs",stdsurvey[[#This Row],[daily_sleep_hours]]<=6,"4-6 hrs",stdsurvey[[#This Row],[daily_sleep_hours]]<=8,"6-8 hrs",TRUE,"> 8 hrs")} -> 6-8 hrs | Y24: Male
A25: STU1021 | B25: 21 | C25: Male | D25: 4 | E25: STEM | F25: 7.1 | G25: 1 | H25: 0 | I25: 7 | J25: 9 | K25: {=_xlfn.IFS(stdsurvey[[#This Row],[phq9_score]]="","Answer Not Provided",stdsurvey[[#This Row],[phq9_score]]<=4,"Minimal",stdsurvey[[#This Row],[phq9_score]]<=9,"Mild",stdsurvey[[#This Row],[phq9_score]]<=14,"Moderate",stdsurvey[[#This Row],[phq9_score]]<=19,"Moderately Severe",stdsurvey[[#This Row],[phq9_score]]<=27,"Severe")} -> Mild | L25: 19 | M25: {=_xlfn.IFS(stdsurvey[[#This Row],[gad7_score]]="","Answer Not Provided",stdsurvey[[#This Row],[gad7_score]]<=4,"Minimal",stdsurvey[[#This Row],[gad7_score]]<=9,"Mild",stdsurvey[[#This Row],[gad7_score]]<=14,"Moderate",stdsurvey[[#This Row],[gad7_score]]<=21,"Severe")} -> Mild | N25: 26.8 | O25: {=_xlfn.IFS(stdsurvey[[#This Row],[perceived_stress_scale]]="","Answer Not Provided",stdsurvey[[#This Row],[perceived_stress_scale]]<=13,"Low Stress",stdsurvey[[#This Row],[perceived_stress_scale]]<=26,"Moderate Stress",stdsurvey[[#This Row],[perceived_stress_scale]]<=40,"High Stress")} -> Moderate Stress | P25: 80 | Q25: 4 | R25: {=_xlfn.IFS(stdsurvey[[#This Row],[class_attendance_percent]]<60,"Less than 0%",stdsurvey[[#This Row],[class_attendance_percent]]<70,"60-70 %",stdsurvey[[#This Row],[class_attendance_percent]]<80, "70-80%",stdsurvey[[#This Row],[class_attendance_percent]]<90,"80-90%",TRUE,"More than 90%")} -> 80-90% | S25: Yes | T25: 4 | U25: Spring | V25: 3.29 | W25: {=_xlfn.IFS( stdsurvey[[#This Row],[daily_screen_time_hours]]<1,"<1 hr", stdsurvey[[#This Row],[daily_screen_time_hours]]<4,"1-4 hrs", stdsurvey[[#This Row],[daily_screen_time_hours]]<8,"4-8 hrs", stdsurvey[[#This Row],[daily_screen_time_hours]]<12,"8-12 hrs", stdsurvey[[#This Row],[daily_screen_time_hours]]<=16,"12-16 hrs", TRUE,">16 hrs" )} -> 1-4 hrs | X25: {=_xlfn.IFS(stdsurvey[[#This Row],[daily_sleep_hours]]<4,"< 4 hrs",stdsurvey[[#This Row],[daily_sleep_hours]]<=6,"4-6 hrs",stdsurvey[[#This Row],[daily_sleep_hours]]<=8,"6-8 hrs",TRUE,"> 8 hrs")} -> 6-8 hrs | Y25: Male
A26: STU1022 | B26: 20 | C26: M | D26: 4 | E26: Social Sciences | F26: 4.5 | G26: 4.3 | H26: 1 | I26: 2 | J26: 2 | K26: {=_xlfn.IFS(stdsurvey[[#This Row],[phq9_score]]="","Answer Not Provided",stdsurvey[[#This Row],[phq9_score]]<=4,"Minimal",stdsurvey[[#This Row],[phq9_score]]<=9,"Mild",stdsurvey[[#This Row],[phq9_score]]<=14,"Moderate",stdsurvey[[#This Row],[phq9_score]]<=19,"Moderately Severe",stdsurvey[[#This Row],[phq9_score]]<=27,"Severe")} -> Minimal | L26: 2 | M26: {=_xlfn.IFS(stdsurvey[[#This Row],[gad7_score]]="","Answer Not Provided",stdsurvey[[#This Row],[gad7_score]]<=4,"Minimal",stdsurvey[[#This Row],[gad7_score]]<=9,"Mild",stdsurvey[[#This Row],[gad7_score]]<=14,"Moderate",stdsurvey[[#This Row],[gad7_score]]<=21,"Severe")} -> Minimal | N26: 14.1 | O26: {=_xlfn.IFS(stdsurvey[[#This Row],[perceived_stress_scale]]="","Answer Not Provided",stdsurvey[[#This Row],[perceived_stress_scale]]<=13,"Low Stress",stdsurvey[[#This Row],[perceived_stress_scale]]<=26,"Moderate Stress",stdsurvey[[#This Row],[perceived_stress_scale]]<=40,"High Stress")} -> Low Stress | P26: 72.7 | Q26: 2 | R26: {=_xlfn.IFS(stdsurvey[[#This Row],[class_attendance_percent]]<60,"Less than 0%",stdsurvey[[#This Row],[class_attendance_percent]]<70,"60-70 %",stdsurvey[[#This Row],[class_attendance_percent]]<80, "70-80%",stdsurvey[[#This Row],[class_attendance_percent]]<90,"80-90%",TRUE,"More than 90%")} -> 70-80% | S26: No | T26: 5 | U26: Spring | V26: 2.88 | W26: {=_xlfn.IFS( stdsurvey[[#This Row],[daily_screen_time_hours]]<1,"<1 hr", stdsurvey[[#This Row],[daily_screen_time_hours]]<4,"1-4 hrs", stdsurvey[[#This Row],[daily_screen_time_hours]]<8,"4-8 hrs", stdsurvey[[#This Row],[daily_screen_time_hours]]<12,"8-12 hrs", stdsurvey[[#This Row],[daily_screen_time_hours]]<=16,"12-16 hrs", TRUE,">16 hrs" )} -> 4-8 hrs | X26: {=_xlfn.IFS(stdsurvey[[#This Row],[daily_sleep_hours]]<4,"< 4 hrs",stdsurvey[[#This Row],[daily_sleep_hours]]<=6,"4-6 hrs",stdsurvey[[#This Row],[daily_sleep_hours]]<=8,"6-8 hrs",TRUE,"> 8 hrs")} -> 4-6 hrs | Y26: Male
A27: STU1023 | B27: 24 | C27: Female | D27: 4 | E27: Health Sciences | F27: 6.4 | G27: 2.4 | H27: 4 | I27: 13 | J27: 9 | K27: {=_xlfn.IFS(stdsurvey[[#This Row],[phq9_score]]="","Answer Not Provided",stdsurvey[[#This Row],[phq9_score]]<=4,"Minimal",stdsurvey[[#This Row],[phq9_score]]<=9,"Mild",stdsurvey[[#This Row],[phq9_score]]<=14,"Moderate",stdsurvey[[#This Row],[phq9_score]]<=19,"Moderately Severe",stdsurvey[[#This Row],[phq9_score]]<=27,"Severe")} -> Moderate | L27: 20 | M27: {=_xlfn.IFS(stdsurvey[[#This Row],[gad7_score]]="","Answer Not Provided",stdsurvey[[#This Row],[gad7_score]]<=4,"Minimal",stdsurvey[[#This Row],[gad7_score]]<=9,"Mild",stdsurvey[[#This Row],[gad7_score]]<=14,"Moderate",stdsurvey[[#This Row],[gad7_score]]<=21,"Severe")} -> Mild | N27: 14.7 | O27: {=_xlfn.IFS(stdsurvey[[#This Row],[perceived_stress_scale]]="","Answer Not Provided",stdsurvey[[#This Row],[perceived_stress_scale]]<=13,"Low Stress",stdsurvey[[#This Row],[perceived_stress_scale]]<=26,"Moderate Stress",stdsurvey[[#This Row],[perceived_stress_scale]]<=40,"High Stress")} -> Moderate Stress | P27: 69.3 | Q27: 2 | R27: {=_xlfn.IFS(stdsurvey[[#This Row],[class_attendance_percent]]<60,"Less than 0%",stdsurvey[[#This Row],[class_attendance_percent]]<70,"60-70 %",stdsurvey[[#This Row],[class_attendance_percent]]<80, "70-80%",stdsurvey[[#This Row],[class_attendance_percent]]<90,"80-90%",TRUE,"More than 90%")} -> 60-70 % | S27: Yes | T27: 2 | U27: Spring | V27: 2.96 | W27: {=_xlfn.IFS( stdsurvey[[#This Row],[daily_screen_time_hours]]<1,"<1 hr", stdsurvey[[#This Row],[daily_screen_time_hours]]<4,"1-4 hrs", stdsurvey[[#This Row],[daily_screen_time_hours]]<8,"4-8 hrs", stdsurvey[[#This Row],[daily_screen_time_hours]]<12,"8-12 hrs", stdsurvey[[#This Row],[daily_screen_time_hours]]<=16,"12-16 hrs", TRUE,">16 hrs" )} -> 1-4 hrs | X27: {=_xlfn.IFS(stdsurvey[[#This Row],[daily_sleep_hours]]<4,"< 4 hrs",stdsurvey[[#This Row],[daily_sleep_hours]]<=6,"4-6 hrs",stdsurvey[[#This Row],[daily_sleep_hours]]<=8,"6-8 hrs",TRUE,"> 8 hrs")} -> 6-8 hrs | Y27: Female
A28: STU1024 | B28: 21 | C28: Female | D28: 5 | E28: STEM | F28: 6.5 | G28: 2.6 | H28: 2 | I28: 25 | J28: 21 | K28: {=_xlfn.IFS(stdsurvey[[#This Row],[phq9_score]]="","Answer Not Provided",stdsurvey[[#This Row],[phq9_score]]<=4,"Minimal",stdsurvey[[#This Row],[phq9_score]]<=9,"Mild",stdsurvey[[#This Row],[phq9_score]]<=14,"Moderate",stdsurvey[[#This Row],[phq9_score]]<=19,"Moderately Severe",stdsurvey[[#This Row],[phq9_score]]<=27,"Severe")} -> Severe | L28: 31 | M28: {=_xlfn.IFS(stdsurvey[[#This Row],[gad7_score]]="","Answer Not Provided",stdsurvey[[#This Row],[gad7_score]]<=4,"Minimal",stdsurvey[[#This Row],[gad7_score]]<=9,"Mild",stdsurvey[[#This Row],[gad7_score]]<=14,"Moderate",stdsurvey[[#This Row],[gad7_score]]<=21,"Severe")} -> Severe | N28: 12.8 | O28: {=_xlfn.IFS(stdsurvey[[#This Row],[perceived_stress_scale]]="","Answer Not Provided",stdsurvey[[#This Row],[perceived_stress_scale]]<=13,"Low Stress",stdsurvey[[#This Row],[perceived_stress_scale]]<=26,"Moderate Stress",stdsurvey[[#This Row],[perceived_stress_scale]]<=40,"High Stress")} -> High Stress | P28: 62.4 | Q28: 1 | R28: {=_xlfn.IFS(stdsurvey[[#This Row],[class_attendance_percent]]<60,"Less than 0%",stdsurvey[[#This Row],[class_attendance_percent]]<70,"60-70 %",stdsurvey[[#This Row],[class_attendance_percent]]<80, "70-80%",stdsurvey[[#This Row],[class_attendance_percent]]<90,"80-90%",TRUE,"More than 90%")} -> 60-70 % | S28: No | T28: 2 | U28: Spring | V28: 2.26 | W28: {=_xlfn.IFS( stdsurvey[[#This Row],[daily_screen_time_hours]]<1,"<1 hr", stdsurvey[[#This Row],[daily_screen_time_hours]]<4,"1-4 hrs", stdsurvey[[#This Row],[daily_screen_time_hours]]<8,"4-8 hrs", stdsurvey[[#This Row],[daily_screen_time_hours]]<12,"8-12 hrs", stdsurvey[[#This Row],[daily_screen_time_hours]]<=16,"12-16 hrs", TRUE,">16 hrs" )} -> 1-4 hrs | X28: {=_xlfn.IFS(stdsurvey[[#This Row],[daily_sleep_hours]]<4,"< 4 hrs",stdsurvey[[#This Row],[daily_sleep_hours]]<=6,"4-6 hrs",stdsurvey[[#This Row],[daily_sleep_hours]]<=8,"6-8 hrs",TRUE,"> 8 hrs")} -> 6-8 hrs | Y28: Female
